{
  "affected_release": null,
  "package_state": [
    {
      "product_name": "Red Hat Software Collections",
      "fix_state": "Under investigation",
      "package_name": "python27-python",
      "cpe": "cpe:/a:redhat:rhel_software_collections:3"
    },
    {
      "product_name": "Red Hat Software Collections",
      "fix_state": "Under investigation",
      "package_name": "rh-python36-python",
      "cpe": "cpe:/a:redhat:rhel_software_collections:3"
    },
    {
      "product_name": "Red Hat Enterprise Linux 5",
      "fix_state": "Under investigation",
      "package_name": "python",
      "cpe": "cpe:/o:redhat:enterprise_linux:5"
    },
    {
      "product_name": "Red Hat Enterprise Linux 6",
      "fix_state": "Under investigation",
      "package_name": "python",
      "cpe": "cpe:/o:redhat:enterprise_linux:6"
    },
    {
      "product_name": "Red Hat Enterprise Linux 7",
      "fix_state": "Under investigation",
      "package_name": "python",
      "cpe": "cpe:/o:redhat:enterprise_linux:7"
    },
    {
      "product_name": "Red Hat Enterprise Linux 7",
      "fix_state": "Under investigation",
      "package_name": "python3",
      "cpe": "cpe:/o:redhat:enterprise_linux:7"
    },
    {
      "product_name": "Red Hat Enterprise Linux 8",
      "fix_state": "Under investigation",
      "package_name": "python27:2.7/python2",
      "cpe": "cpe:/o:redhat:enterprise_linux:8"
    },
    {
      "product_name": "Red Hat Enterprise Linux 8",
      "fix_state": "Under investigation",
      "package_name": "python3",
      "cpe": "cpe:/o:redhat:enterprise_linux:8"
    },
    {
      "product_name": "Red Hat Enterprise Linux 8",
      "fix_state": "Under investigation",
      "package_name": "python36:3.6/python36",
      "cpe": "cpe:/o:redhat:enterprise_linux:8"
    }
  ],
  "threat_severity": "Important",
  "public_date": "2020-03-02T00:00:00Z",
  "bugzilla": {
    "description": "CVE-2020-8492 python: wrong backtracking in urllib.request.AbstractBasicAuthHandler allows for a ReDoS",
    "id": "1809065",
    "url": "https://bugzilla.redhat.com/show_bug.cgi?id=1809065"
  },
  "cvss": {
    "cvss_base_score": "",
    "cvss_scoring_vector": "",
    "status": ""
  },
  "cvss3": {
    "cvss3_base_score": "7.5",
    "cvss3_scoring_vector": "CVSS:3.1/AV:N/AC:L/PR:N/UI:N/S:U/C:N/I:N/A:H",
    "status": "draft"
  },
  "iava": "",
  "cwe": "CWE-400",
  "statement": "",
  "acknowledgement": "",
  "name": "CVE-2020-8492",
  "document_distribution": "",
  "details": [
    "Python 2.7 through 2.7.17, 3.5 through 3.5.9, 3.6 through 3.6.10, 3.7 through 3.7.6, and 3.8 through 3.8.1 allows an HTTP server to conduct Regular Expression Denial of Service (ReDoS) attacks against a client because of urllib.request.AbstractBasicAuthHandler catastrophic backtracking."
  ],
  "references": null
}