{
  "configurations": {
    "CVE_data_version": "4.0",
    "nodes": [
      {
        "cpe_match": [
          {
            "cpe23Uri": "cpe:2.3:a:python:python:*:*:*:*:*:*:*:*",
            "versionEndIncluding": "3.7.2",
            "vulnerable": true
          }
        ],
        "operator": "OR"
      }
    ]
  },
  "cve": {
    "CVE_data_meta": {
      "ASSIGNER": "cve@mitre.org",
      "ID": "CVE-2019-9674"
    },
    "affects": {
      "vendor": {
        "vendor_data": [
          {
            "product": {
              "product_data": [
                {
                  "product_name": "python",
                  "version": {
                    "version_data": [
                      {
                        "version_affected": "\u003c=",
                        "version_value": "3.7.2"
                      }
                    ]
                  }
                }
              ]
            },
            "vendor_name": "python"
          }
        ]
      }
    },
    "data_format": "MITRE",
    "data_type": "CVE",
    "data_version": "4.0",
    "description": {
      "description_data": [
        {
          "lang": "en",
          "value": "Lib/zipfile.py in Python through 3.7.2 allows remote attackers to cause a denial of service (resource consumption) via a ZIP bomb."
        }
      ]
    },
    "problemtype": {
      "problemtype_data": [
        {
          "description": [
            {
              "lang": "en",
              "value": "CWE-400"
            }
          ]
        }
      ]
    },
    "references": {
      "reference_data": [
        {
          "name": "https://bugs.python.org/issue36260",
          "refsource": "MISC",
          "tags": [
            "Issue Tracking",
            "Vendor Advisory"
          ],
          "url": "https://bugs.python.org/issue36260"
        },
        {
          "name": "https://bugs.python.org/issue36462",
          "refsource": "MISC",
          "tags": [
            "Issue Tracking",
            "Vendor Advisory"
          ],
          "url": "https://bugs.python.org/issue36462"
        },
        {
          "name": "https://github.com/python/cpython/blob/master/Lib/zipfile.py",
          "refsource": "MISC",
          "tags": [
            "Third Party Advisory"
          ],
          "url": "https://github.com/python/cpython/blob/master/Lib/zipfile.py"
        },
        {
          "name": "https://python-security.readthedocs.io/security.html#archives-and-zip-bomb",
          "refsource": "MISC",
          "tags": [
            "Vendor Advisory"
          ],
          "url": "https://python-security.readthedocs.io/security.html#archives-and-zip-bomb"
        },
        {
          "name": "https://www.python.org/news/security/",
          "refsource": "MISC",
          "tags": [
            "Vendor Advisory"
          ],
          "url": "https://www.python.org/news/security/"
        }
      ]
    }
  },
  "impact": {
    "baseMetricV2": {
      "acInsufInfo": false,
      "cvssV2": {
        "accessComplexity": "MEDIUM",
        "accessVector": "NETWORK",
        "authentication": "NONE",
        "availabilityImpact": "COMPLETE",
        "baseScore": 7.1,
        "confidentialityImpact": "NONE",
        "integrityImpact": "NONE",
        "vectorString": "AV:N/AC:M/Au:N/C:N/I:N/A:C",
        "version": "2.0"
      },
      "exploitabilityScore": 8.6,
      "impactScore": 6.9,
      "obtainAllPrivilege": false,
      "obtainOtherPrivilege": false,
      "obtainUserPrivilege": false,
      "severity": "HIGH",
      "userInteractionRequired": true
    }
  },
  "lastModifiedDate": "2020-02-06T15:14Z",
  "publishedDate": "2020-02-04T15:15Z"
}