{
  "acknowledgement": "\nRed Hat would like to thank the upstream Django project for reporting this issue.\n    ",
  "bugzilla": {
    "description": "\nCVE-2015-5145 Django: DoS via incorrect URL validation\n    ",
    "id": "1240526",
    "url": "https://bugzilla.redhat.com/show_bug.cgi?id=1240526"
  },
  "cvss": {
    "cvss_base_score": "5.0",
    "cvss_scoring_vector": "AV:N/AC:L/Au:N/C:N/I:N/A:P",
    "status": "draft"
  },
  "cwe": "CWE-185",
  "details": [
    "\nvalidators.URLValidator in Django 1.8.x before 1.8.3 allows remote attackers to cause a denial of service (CPU consumption) via unspecified vectors.\n    "
  ],
  "name": "CVE-2015-5145",
  "package_state": [
    {
      "cpe": "cpe:/a:redhat:openstack:5",
      "fix_state": "Not affected",
      "package_name": "python-django",
      "product_name": "Red Hat Enterprise Linux OpenStack Platform 5.0 (Icehouse)"
    },
    {
      "cpe": "cpe:/a:redhat:openstack:6",
      "fix_state": "Not affected",
      "package_name": "python-django",
      "product_name": "Red Hat Enterprise Linux OpenStack Platform 6.0 (Juno) for RHEL 7"
    },
    {
      "cpe": "cpe:/a:redhat:openstack:7",
      "fix_state": "Not affected",
      "package_name": "python-django",
      "product_name": "Red Hat Enterprise Linux OpenStack Platform 7.0 (Kilo) for RHEL 7"
    },
    {
      "cpe": "cpe:/a:redhat:rhel_sam:1",
      "fix_state": "Not affected",
      "package_name": "Django",
      "product_name": "Red Hat Subscription Asset Manager 1"
    }
  ],
  "public_date": "2015-07-08T00:00:00",
  "threat_severity": "Moderate",
  "upstream_fix": "Django 1.8.3"
}